<?xml version="1.0"?>
<robot name="simple_box">

    <link name="dummy" />
    <joint name="dummy_joint" type="fixed">
        <parent link="dummy"/>
        <child link="base_link"/>
    </joint>

    <link name="base_link">
        <inertial>
            <origin xyz="0.0 0.0 0.0" rpy="0.0 0.0 0.0"/>
            <mass value="10"/>
            <inertia ixx="0.0013" ixy="0.0" ixz="0.0" iyy="0.0013" iyz="0.0" izz="0.0013"/>
        </inertial>
        <visual>
            <origin xyz="0.0 0.05 0.01" />
            <geometry>
                <box size="0.2 0.1 0.02"/>
            </geometry>
        </visual>
        <collision>
            <origin xyz="0.0 0.0 0.025" />
            <geometry>
                <box size="0.2 0.2 0.05"/>
            </geometry>
        </collision>
    </link>

    <link name="link_box">
        <inertial>
            <origin xyz="0.0 0.0 0.0" rpy="0.0 0.0 0.0"/>
            <mass value="0.2"/>
            <inertia ixx="0.0013" ixy="0.0" ixz="0.0" iyy="0.0013" iyz="0.0" izz="0.0013"/>
        </inertial>
        <visual>
            <origin xyz="0.0 0.0 0.122" rpy="0.0 0.0 1.0" />
            <geometry>
                <box size="0.2 0.2 0.2"/>
            </geometry>
        </visual>
        <collision>
            <origin xyz="0.0 0.0 0.1" />
            <geometry>
                <box size="0.2 0.2 0.2"/>
            </geometry>
        </collision>
    </link>

    <joint name="joint_box" type="revolute">
        <origin xyz="0.0 0.0 0.0" rpy="0.0 0.0 0.0"/>
        <parent link="base_link"/>
        <child link="link_box"/>
        <axis xyz="1.0 0.0 0.0"/>
        <limit lower="-3.14" upper="3.14" effort="100.0" velocity="0.2"/>
    </joint>

    <transmission name="trans_box">
        <type>transmission_interface/SimpleTransmission</type>
        <joint name="joint_box">
            <hardwareInterface>hardware_interface/PositionJointInterface</hardwareInterface>
        </joint>
        <actuator name="motor_box">
            <hardwareInterface>hardware_interface/PositionJointInterface</hardwareInterface>
            <mechanicalReduction>1</mechanicalReduction>
        </actuator>
    </transmission>

    <gazebo>
        <plugin name="ros_control" filename="libgazebo_ros_control.so" />
    </gazebo>

    <gazebo reference="link_box" >
        <material>Gazebo/Blue</material>
    </gazebo>


</robot>